2021-02-19 13:09:05,977 - INFO -  * Running on http://0.0.0.0:8080/ (Press CTRL+C to quit)
2021-02-19 13:09:07,039 - ERROR - Exception on / [GET]
Traceback (most recent call last):
  File "/opt/virtualenvs/python3/lib/python3.8/site-packages/flask/app.py", line 2447, in wsgi_app
    response = self.full_dispatch_request()
  File "/opt/virtualenvs/python3/lib/python3.8/site-packages/flask/app.py", line 1952, in full_dispatch_request
    rv = self.handle_user_exception(e)
  File "/opt/virtualenvs/python3/lib/python3.8/site-packages/flask/app.py", line 1821, in handle_user_exception
    reraise(exc_type, exc_value, tb)
  File "/opt/virtualenvs/python3/lib/python3.8/site-packages/flask/_compat.py", line 39, in reraise
    raise value
  File "/opt/virtualenvs/python3/lib/python3.8/site-packages/flask/app.py", line 1950, in full_dispatch_request
    rv = self.dispatch_request()
  File "/opt/virtualenvs/python3/lib/python3.8/site-packages/flask/app.py", line 1936, in dispatch_request
    return self.view_functions[rule.endpoint](**req.view_args)
  File "/home/runner/Kids-Code-Python/run.py", line 32, in index
    return render_template('index.html')
  File "/opt/virtualenvs/python3/lib/python3.8/site-packages/flask/templating.py", line 138, in render_template
    ctx.app.jinja_env.get_or_select_template(template_name_or_list),
  File "/opt/virtualenvs/python3/lib/python3.8/site-packages/jinja2/environment.py", line 930, in get_or_select_template
    return self.get_template(template_name_or_list, parent, globals)
  File "/opt/virtualenvs/python3/lib/python3.8/site-packages/jinja2/environment.py", line 883, in get_template
    return self._load_template(name, self.make_globals(globals))
  File "/opt/virtualenvs/python3/lib/python3.8/site-packages/jinja2/environment.py", line 857, in _load_template
    template = self.loader.load(self, name, globals)
  File "/opt/virtualenvs/python3/lib/python3.8/site-packages/jinja2/loaders.py", line 115, in load
    source, filename, uptodate = self.get_source(environment, name)
  File "/opt/virtualenvs/python3/lib/python3.8/site-packages/flask/templating.py", line 60, in get_source
    return self._get_source_fast(environment, template)
  File "/opt/virtualenvs/python3/lib/python3.8/site-packages/flask/templating.py", line 89, in _get_source_fast
    raise TemplateNotFound(template)
jinja2.exceptions.TemplateNotFound: index.html
2021-02-19 13:09:07,151 - INFO - 172.18.0.1 - - [19/Feb/2021 13:09:07] "[35m[1mGET / HTTP/1.1[0m" 500 -
2021-02-19 13:09:23,071 - INFO -  * Running on http://0.0.0.0:8080/ (Press CTRL+C to quit)
2021-02-19 13:09:24,123 - ERROR - Exception on / [GET]
Traceback (most recent call last):
  File "/opt/virtualenvs/python3/lib/python3.8/site-packages/flask/app.py", line 2447, in wsgi_app
    response = self.full_dispatch_request()
  File "/opt/virtualenvs/python3/lib/python3.8/site-packages/flask/app.py", line 1952, in full_dispatch_request
    rv = self.handle_user_exception(e)
  File "/opt/virtualenvs/python3/lib/python3.8/site-packages/flask/app.py", line 1821, in handle_user_exception
    reraise(exc_type, exc_value, tb)
  File "/opt/virtualenvs/python3/lib/python3.8/site-packages/flask/_compat.py", line 39, in reraise
    raise value
  File "/opt/virtualenvs/python3/lib/python3.8/site-packages/flask/app.py", line 1950, in full_dispatch_request
    rv = self.dispatch_request()
  File "/opt/virtualenvs/python3/lib/python3.8/site-packages/flask/app.py", line 1936, in dispatch_request
    return self.view_functions[rule.endpoint](**req.view_args)
  File "run.py", line 32, in index
    return render_template('index.html')
  File "/opt/virtualenvs/python3/lib/python3.8/site-packages/flask/templating.py", line 138, in render_template
    ctx.app.jinja_env.get_or_select_template(template_name_or_list),
  File "/opt/virtualenvs/python3/lib/python3.8/site-packages/jinja2/environment.py", line 930, in get_or_select_template
    return self.get_template(template_name_or_list, parent, globals)
  File "/opt/virtualenvs/python3/lib/python3.8/site-packages/jinja2/environment.py", line 883, in get_template
    return self._load_template(name, self.make_globals(globals))
  File "/opt/virtualenvs/python3/lib/python3.8/site-packages/jinja2/environment.py", line 857, in _load_template
    template = self.loader.load(self, name, globals)
  File "/opt/virtualenvs/python3/lib/python3.8/site-packages/jinja2/loaders.py", line 115, in load
    source, filename, uptodate = self.get_source(environment, name)
  File "/opt/virtualenvs/python3/lib/python3.8/site-packages/flask/templating.py", line 60, in get_source
    return self._get_source_fast(environment, template)
  File "/opt/virtualenvs/python3/lib/python3.8/site-packages/flask/templating.py", line 89, in _get_source_fast
    raise TemplateNotFound(template)
jinja2.exceptions.TemplateNotFound: index.html
2021-02-19 13:09:24,130 - INFO - 172.18.0.1 - - [19/Feb/2021 13:09:24] "[35m[1mGET / HTTP/1.1[0m" 500 -
2021-02-19 13:09:30,526 - ERROR - Exception on / [GET]
Traceback (most recent call last):
  File "/opt/virtualenvs/python3/lib/python3.8/site-packages/flask/app.py", line 2447, in wsgi_app
    response = self.full_dispatch_request()
  File "/opt/virtualenvs/python3/lib/python3.8/site-packages/flask/app.py", line 1952, in full_dispatch_request
    rv = self.handle_user_exception(e)
  File "/opt/virtualenvs/python3/lib/python3.8/site-packages/flask/app.py", line 1821, in handle_user_exception
    reraise(exc_type, exc_value, tb)
  File "/opt/virtualenvs/python3/lib/python3.8/site-packages/flask/_compat.py", line 39, in reraise
    raise value
  File "/opt/virtualenvs/python3/lib/python3.8/site-packages/flask/app.py", line 1950, in full_dispatch_request
    rv = self.dispatch_request()
  File "/opt/virtualenvs/python3/lib/python3.8/site-packages/flask/app.py", line 1936, in dispatch_request
    return self.view_functions[rule.endpoint](**req.view_args)
  File "run.py", line 32, in index
    return render_template('index.html')
  File "/opt/virtualenvs/python3/lib/python3.8/site-packages/flask/templating.py", line 138, in render_template
    ctx.app.jinja_env.get_or_select_template(template_name_or_list),
  File "/opt/virtualenvs/python3/lib/python3.8/site-packages/jinja2/environment.py", line 930, in get_or_select_template
    return self.get_template(template_name_or_list, parent, globals)
  File "/opt/virtualenvs/python3/lib/python3.8/site-packages/jinja2/environment.py", line 883, in get_template
    return self._load_template(name, self.make_globals(globals))
  File "/opt/virtualenvs/python3/lib/python3.8/site-packages/jinja2/environment.py", line 857, in _load_template
    template = self.loader.load(self, name, globals)
  File "/opt/virtualenvs/python3/lib/python3.8/site-packages/jinja2/loaders.py", line 115, in load
    source, filename, uptodate = self.get_source(environment, name)
  File "/opt/virtualenvs/python3/lib/python3.8/site-packages/flask/templating.py", line 60, in get_source
    return self._get_source_fast(environment, template)
  File "/opt/virtualenvs/python3/lib/python3.8/site-packages/flask/templating.py", line 89, in _get_source_fast
    raise TemplateNotFound(template)
jinja2.exceptions.TemplateNotFound: index.html
2021-02-19 13:09:30,528 - INFO - 172.18.0.1 - - [19/Feb/2021 13:09:30] "[35m[1mGET / HTTP/1.1[0m" 500 -
2021-02-19 13:09:46,793 - INFO -  * Running on http://0.0.0.0:8080/ (Press CTRL+C to quit)
2021-02-19 13:09:48,654 - ERROR - Exception on / [GET]
Traceback (most recent call last):
  File "/opt/virtualenvs/python3/lib/python3.8/site-packages/flask/app.py", line 2447, in wsgi_app
    response = self.full_dispatch_request()
  File "/opt/virtualenvs/python3/lib/python3.8/site-packages/flask/app.py", line 1952, in full_dispatch_request
    rv = self.handle_user_exception(e)
  File "/opt/virtualenvs/python3/lib/python3.8/site-packages/flask/app.py", line 1821, in handle_user_exception
    reraise(exc_type, exc_value, tb)
  File "/opt/virtualenvs/python3/lib/python3.8/site-packages/flask/_compat.py", line 39, in reraise
    raise value
  File "/opt/virtualenvs/python3/lib/python3.8/site-packages/flask/app.py", line 1950, in full_dispatch_request
    rv = self.dispatch_request()
  File "/opt/virtualenvs/python3/lib/python3.8/site-packages/flask/app.py", line 1936, in dispatch_request
    return self.view_functions[rule.endpoint](**req.view_args)
  File "run.py", line 31, in index
    return render_template('index.html')
  File "/opt/virtualenvs/python3/lib/python3.8/site-packages/flask/templating.py", line 138, in render_template
    ctx.app.jinja_env.get_or_select_template(template_name_or_list),
  File "/opt/virtualenvs/python3/lib/python3.8/site-packages/jinja2/environment.py", line 930, in get_or_select_template
    return self.get_template(template_name_or_list, parent, globals)
  File "/opt/virtualenvs/python3/lib/python3.8/site-packages/jinja2/environment.py", line 883, in get_template
    return self._load_template(name, self.make_globals(globals))
  File "/opt/virtualenvs/python3/lib/python3.8/site-packages/jinja2/environment.py", line 857, in _load_template
    template = self.loader.load(self, name, globals)
  File "/opt/virtualenvs/python3/lib/python3.8/site-packages/jinja2/loaders.py", line 115, in load
    source, filename, uptodate = self.get_source(environment, name)
  File "/opt/virtualenvs/python3/lib/python3.8/site-packages/flask/templating.py", line 60, in get_source
    return self._get_source_fast(environment, template)
  File "/opt/virtualenvs/python3/lib/python3.8/site-packages/flask/templating.py", line 89, in _get_source_fast
    raise TemplateNotFound(template)
jinja2.exceptions.TemplateNotFound: index.html
2021-02-19 13:09:48,659 - INFO - 172.18.0.1 - - [19/Feb/2021 13:09:48] "[35m[1mGET / HTTP/1.1[0m" 500 -
2021-02-19 13:10:43,442 - ERROR - Exception on / [GET]
Traceback (most recent call last):
  File "/opt/virtualenvs/python3/lib/python3.8/site-packages/flask/app.py", line 2447, in wsgi_app
    response = self.full_dispatch_request()
  File "/opt/virtualenvs/python3/lib/python3.8/site-packages/flask/app.py", line 1952, in full_dispatch_request
    rv = self.handle_user_exception(e)
  File "/opt/virtualenvs/python3/lib/python3.8/site-packages/flask/app.py", line 1821, in handle_user_exception
    reraise(exc_type, exc_value, tb)
  File "/opt/virtualenvs/python3/lib/python3.8/site-packages/flask/_compat.py", line 39, in reraise
    raise value
  File "/opt/virtualenvs/python3/lib/python3.8/site-packages/flask/app.py", line 1950, in full_dispatch_request
    rv = self.dispatch_request()
  File "/opt/virtualenvs/python3/lib/python3.8/site-packages/flask/app.py", line 1936, in dispatch_request
    return self.view_functions[rule.endpoint](**req.view_args)
  File "run.py", line 31, in index
    return render_template('index.html')
  File "/opt/virtualenvs/python3/lib/python3.8/site-packages/flask/templating.py", line 138, in render_template
    ctx.app.jinja_env.get_or_select_template(template_name_or_list),
  File "/opt/virtualenvs/python3/lib/python3.8/site-packages/jinja2/environment.py", line 930, in get_or_select_template
    return self.get_template(template_name_or_list, parent, globals)
  File "/opt/virtualenvs/python3/lib/python3.8/site-packages/jinja2/environment.py", line 883, in get_template
    return self._load_template(name, self.make_globals(globals))
  File "/opt/virtualenvs/python3/lib/python3.8/site-packages/jinja2/environment.py", line 857, in _load_template
    template = self.loader.load(self, name, globals)
  File "/opt/virtualenvs/python3/lib/python3.8/site-packages/jinja2/loaders.py", line 115, in load
    source, filename, uptodate = self.get_source(environment, name)
  File "/opt/virtualenvs/python3/lib/python3.8/site-packages/flask/templating.py", line 60, in get_source
    return self._get_source_fast(environment, template)
  File "/opt/virtualenvs/python3/lib/python3.8/site-packages/flask/templating.py", line 89, in _get_source_fast
    raise TemplateNotFound(template)
jinja2.exceptions.TemplateNotFound: index.html
2021-02-19 13:10:43,443 - INFO - 172.18.0.1 - - [19/Feb/2021 13:10:43] "[35m[1mGET / HTTP/1.1[0m" 500 -
2021-02-19 13:14:04,873 - ERROR - Exception on / [GET]
Traceback (most recent call last):
  File "/opt/virtualenvs/python3/lib/python3.8/site-packages/flask/app.py", line 2447, in wsgi_app
    response = self.full_dispatch_request()
  File "/opt/virtualenvs/python3/lib/python3.8/site-packages/flask/app.py", line 1952, in full_dispatch_request
    rv = self.handle_user_exception(e)
  File "/opt/virtualenvs/python3/lib/python3.8/site-packages/flask/app.py", line 1821, in handle_user_exception
    reraise(exc_type, exc_value, tb)
  File "/opt/virtualenvs/python3/lib/python3.8/site-packages/flask/_compat.py", line 39, in reraise
    raise value
  File "/opt/virtualenvs/python3/lib/python3.8/site-packages/flask/app.py", line 1950, in full_dispatch_request
    rv = self.dispatch_request()
  File "/opt/virtualenvs/python3/lib/python3.8/site-packages/flask/app.py", line 1936, in dispatch_request
    return self.view_functions[rule.endpoint](**req.view_args)
  File "run.py", line 31, in index
    return render_template('index.html')
  File "/opt/virtualenvs/python3/lib/python3.8/site-packages/flask/templating.py", line 138, in render_template
    ctx.app.jinja_env.get_or_select_template(template_name_or_list),
  File "/opt/virtualenvs/python3/lib/python3.8/site-packages/jinja2/environment.py", line 930, in get_or_select_template
    return self.get_template(template_name_or_list, parent, globals)
  File "/opt/virtualenvs/python3/lib/python3.8/site-packages/jinja2/environment.py", line 883, in get_template
    return self._load_template(name, self.make_globals(globals))
  File "/opt/virtualenvs/python3/lib/python3.8/site-packages/jinja2/environment.py", line 857, in _load_template
    template = self.loader.load(self, name, globals)
  File "/opt/virtualenvs/python3/lib/python3.8/site-packages/jinja2/loaders.py", line 115, in load
    source, filename, uptodate = self.get_source(environment, name)
  File "/opt/virtualenvs/python3/lib/python3.8/site-packages/flask/templating.py", line 60, in get_source
    return self._get_source_fast(environment, template)
  File "/opt/virtualenvs/python3/lib/python3.8/site-packages/flask/templating.py", line 89, in _get_source_fast
    raise TemplateNotFound(template)
jinja2.exceptions.TemplateNotFound: index.html
2021-02-19 13:14:04,875 - INFO - 172.18.0.1 - - [19/Feb/2021 13:14:04] "[35m[1mGET / HTTP/1.1[0m" 500 -
2021-02-19 13:14:34,490 - INFO -  * Running on http://0.0.0.0:8080/ (Press CTRL+C to quit)
2021-02-19 13:15:32,776 - ERROR - Exception on / [GET]
Traceback (most recent call last):
  File "/opt/virtualenvs/python3/lib/python3.8/site-packages/flask/app.py", line 2447, in wsgi_app
    response = self.full_dispatch_request()
  File "/opt/virtualenvs/python3/lib/python3.8/site-packages/flask/app.py", line 1952, in full_dispatch_request
    rv = self.handle_user_exception(e)
  File "/opt/virtualenvs/python3/lib/python3.8/site-packages/flask/app.py", line 1821, in handle_user_exception
    reraise(exc_type, exc_value, tb)
  File "/opt/virtualenvs/python3/lib/python3.8/site-packages/flask/_compat.py", line 39, in reraise
    raise value
  File "/opt/virtualenvs/python3/lib/python3.8/site-packages/flask/app.py", line 1948, in full_dispatch_request
    rv = self.preprocess_request()
  File "/opt/virtualenvs/python3/lib/python3.8/site-packages/flask/app.py", line 2242, in preprocess_request
    rv = func()
  File "run.py", line 21, in before_request
    tests.test(app)
AttributeError: module 'python.tests' has no attribute 'test'
2021-02-19 13:15:32,780 - INFO - 172.18.0.1 - - [19/Feb/2021 13:15:32] "[35m[1mGET / HTTP/1.1[0m" 500 -
2021-02-19 13:17:53,686 - ERROR - Exception on / [GET]
Traceback (most recent call last):
  File "/opt/virtualenvs/python3/lib/python3.8/site-packages/flask/app.py", line 2447, in wsgi_app
    response = self.full_dispatch_request()
  File "/opt/virtualenvs/python3/lib/python3.8/site-packages/flask/app.py", line 1952, in full_dispatch_request
    rv = self.handle_user_exception(e)
  File "/opt/virtualenvs/python3/lib/python3.8/site-packages/flask/app.py", line 1821, in handle_user_exception
    reraise(exc_type, exc_value, tb)
  File "/opt/virtualenvs/python3/lib/python3.8/site-packages/flask/_compat.py", line 39, in reraise
    raise value
  File "/opt/virtualenvs/python3/lib/python3.8/site-packages/flask/app.py", line 1948, in full_dispatch_request
    rv = self.preprocess_request()
  File "/opt/virtualenvs/python3/lib/python3.8/site-packages/flask/app.py", line 2242, in preprocess_request
    rv = func()
  File "run.py", line 21, in before_request
    tests.test(app)
AttributeError: module 'python.tests' has no attribute 'test'
2021-02-19 13:17:53,687 - INFO - 172.18.0.1 - - [19/Feb/2021 13:17:53] "[35m[1mGET / HTTP/1.1[0m" 500 -
2021-02-19 13:17:57,116 - INFO -  * Running on http://0.0.0.0:8080/ (Press CTRL+C to quit)
2021-02-19 13:17:57,695 - ERROR - Exception on / [GET]
Traceback (most recent call last):
  File "/opt/virtualenvs/python3/lib/python3.8/site-packages/flask/app.py", line 2447, in wsgi_app
    response = self.full_dispatch_request()
  File "/opt/virtualenvs/python3/lib/python3.8/site-packages/flask/app.py", line 1952, in full_dispatch_request
    rv = self.handle_user_exception(e)
  File "/opt/virtualenvs/python3/lib/python3.8/site-packages/flask/app.py", line 1821, in handle_user_exception
    reraise(exc_type, exc_value, tb)
  File "/opt/virtualenvs/python3/lib/python3.8/site-packages/flask/_compat.py", line 39, in reraise
    raise value
  File "/opt/virtualenvs/python3/lib/python3.8/site-packages/flask/app.py", line 1948, in full_dispatch_request
    rv = self.preprocess_request()
  File "/opt/virtualenvs/python3/lib/python3.8/site-packages/flask/app.py", line 2242, in preprocess_request
    rv = func()
  File "run.py", line 21, in before_request
    tests.test(app)
AttributeError: module 'python.tests' has no attribute 'test'
2021-02-19 13:17:57,700 - INFO - 172.18.0.1 - - [19/Feb/2021 13:17:57] "[35m[1mGET / HTTP/1.1[0m" 500 -
2021-02-19 13:18:00,292 - ERROR - Exception on / [GET]
Traceback (most recent call last):
  File "/opt/virtualenvs/python3/lib/python3.8/site-packages/flask/app.py", line 2447, in wsgi_app
    response = self.full_dispatch_request()
  File "/opt/virtualenvs/python3/lib/python3.8/site-packages/flask/app.py", line 1952, in full_dispatch_request
    rv = self.handle_user_exception(e)
  File "/opt/virtualenvs/python3/lib/python3.8/site-packages/flask/app.py", line 1821, in handle_user_exception
    reraise(exc_type, exc_value, tb)
  File "/opt/virtualenvs/python3/lib/python3.8/site-packages/flask/_compat.py", line 39, in reraise
    raise value
  File "/opt/virtualenvs/python3/lib/python3.8/site-packages/flask/app.py", line 1948, in full_dispatch_request
    rv = self.preprocess_request()
  File "/opt/virtualenvs/python3/lib/python3.8/site-packages/flask/app.py", line 2242, in preprocess_request
    rv = func()
  File "run.py", line 21, in before_request
    tests.test(app)
AttributeError: module 'python.tests' has no attribute 'test'
2021-02-19 13:18:00,293 - INFO - 172.18.0.1 - - [19/Feb/2021 13:18:00] "[35m[1mGET / HTTP/1.1[0m" 500 -
2021-02-19 13:18:00,674 - ERROR - Exception on /favicon.ico [GET]
Traceback (most recent call last):
  File "/opt/virtualenvs/python3/lib/python3.8/site-packages/flask/app.py", line 2447, in wsgi_app
    response = self.full_dispatch_request()
  File "/opt/virtualenvs/python3/lib/python3.8/site-packages/flask/app.py", line 1952, in full_dispatch_request
    rv = self.handle_user_exception(e)
  File "/opt/virtualenvs/python3/lib/python3.8/site-packages/flask/app.py", line 1821, in handle_user_exception
    reraise(exc_type, exc_value, tb)
  File "/opt/virtualenvs/python3/lib/python3.8/site-packages/flask/_compat.py", line 39, in reraise
    raise value
  File "/opt/virtualenvs/python3/lib/python3.8/site-packages/flask/app.py", line 1948, in full_dispatch_request
    rv = self.preprocess_request()
  File "/opt/virtualenvs/python3/lib/python3.8/site-packages/flask/app.py", line 2242, in preprocess_request
    rv = func()
  File "run.py", line 21, in before_request
    tests.test(app)
AttributeError: module 'python.tests' has no attribute 'test'
2021-02-19 13:18:00,676 - INFO - 172.18.0.1 - - [19/Feb/2021 13:18:00] "[35m[1mGET /favicon.ico HTTP/1.1[0m" 500 -
